Workbook
Name _____________HAL4: NA()
Name ________AAD3: #N/A
Name ______AAD3: #N/A
Name ______new5: #N/A
Name _____new5: #N/A
Name ____AAD3: #N/A
Name ____HAL4_2: NA()
Name ____new5: #N/A
Name ___ker3030: [1]harsat!$H$18
Name __bes39: '[5]Sat Bah & Up'!$G$58
Name __cat2: [6]Upah!$D$24
Name __cat3: [6]Upah!$D$25
Name __cle65: '[7]BAG-III'!$J$303
Name __faw10: '[7]BAG-III'!$J$316
Name __faw65: '[7]BAG-III'!$J$317
Name __gen1000: [8]Ahs.2!$L$313
Name __GID1: '[9]LKVL-CK-HT-GD1'!$A$4
Name __gip15: '[7]BAG-III'!$J$294
Name __gip20: '[7]BAG-III'!$J$293
Name __gip25: '[7]BAG-III'!$J$292
Name __gip32: '[7]BAG-III'!$J$291
Name __gip40: '[7]BAG-III'!$J$290
Name __gip50: '[7]BAG-III'!$J$289
Name __gra6060: [1]harsat!$H$27
Name __int2: '[10]Harga satuan'!$N$3
Name __mp3: [8]Ahs.1!$N$1149
Name __paw25: '[7]BAG-III'!$J$313
Name __paw40: '[7]BAG-III'!$J$312
Name __paw50: '[7]BAG-III'!$J$311
Name __paw65: '[7]BAG-III'!$J$310
Name __pek2: [6]Upah!$D$15
Name __pek3: [6]Upah!$D$16
Name __ups10: [8]Ahs.2!$L$525
Name _12Excel_BuiltIn_Print_Area_1_1: '[13]Spec Str'!$A$2:$E$60,'[13]Spec Str'!$A$2:$E$60
Name _13Excel_BuiltIn_Print_Area_9_1: #REF!,#REF!
Name _13Excel_BuiltIn_Print_Area_9_1: #REF!,#REF!
Name _13Excel_BuiltIn_Print_Area_9_1: #REF!,#REF!
Name _13Excel_BuiltIn_Print_Area_9_1: #REF!,#REF!
Name _13Excel_BuiltIn_Print_Area_9_1: #REF!,#REF!
Name _13Excel_BuiltIn_Print_Area_9_1: #REF!,#REF!
Name _13Excel_BuiltIn_Print_Area_9_1: #REF!,#REF!
Name _14Excel_BuiltIn_Print_Titles_4_1_1: #REF!,#REF!
Name _14Excel_BuiltIn_Print_Titles_4_1_1: #REF!,#REF!
Name _14Excel_BuiltIn_Print_Titles_4_1_1: #REF!,#REF!
Name _14Excel_BuiltIn_Print_Titles_4_1_1: #REF!,#REF!
Name _14Excel_BuiltIn_Print_Titles_4_1_1: #REF!,#REF!
Name _14Excel_BuiltIn_Print_Titles_4_1_1: #REF!,#REF!
Name _21Excel_BuiltIn_Print_Area_9_1: #REF!,#REF!
Name _21Excel_BuiltIn_Print_Area_9_1: #REF!,#REF!
Name _21Excel_BuiltIn_Print_Area_9_1: #REF!,#REF!
Name _21Excel_BuiltIn_Print_Area_9_1: #REF!,#REF!
Name _21Excel_BuiltIn_Print_Area_9_1: #REF!,#REF!
Name _21Excel_BuiltIn_Print_Area_9_1: #REF!,#REF!
Name _39Excel_BuiltIn_Print_Titles_4_1_1: #REF!,#REF!
Name _39Excel_BuiltIn_Print_Titles_4_1_1: #REF!,#REF!
Name _39Excel_BuiltIn_Print_Titles_4_1_1: #REF!,#REF!
Name _A_2: NA()
Name _AAD3: HAJIME:OWARI
Name _AAD3: [15]!HAJIME:[15]!OWARI
Name _AAD3: [0]!HAJIME:[0]!OWARI

Sheet Plumbing
A1: Perhitungan Volume Plumbing
A3: Proyek | B3: : DHR C2
A5: Lantai | B5: Nomor | C5: Pipa Air Hujan Horizontal (2.5") | D5: Pipa Air Hujan Vertikal (2.5") | E5: Pipa Air Hujan Horizontal (4") | F5: Pipa Air Hujan Vertikal (4") | G5: Pipa Air Hujan Horizontal (6") | H5: Pipa Air Hujan Vertikal (6") | I5: Pipa Air Hujan Utama (8") | K5: Pipa Air Kotor Horizontal (1.5") | L5: Pipa Air Kotor Vertikal (1.5") | M5: Pipa Air Kotor Horizontal (3") | N5: Pipa Air Kotor Vertikal (3") | O5: Pipa Kitchen Horizontal (3") | P5: Pipa Kitchen Vertikal (3") | R5: Pipa WC Vertikal (3") | S5: Pipa WC Horizontal (3") | T5: Pipa Hawa Septic Tank Horizontal (1.5") | U5: Pipa Hawa Septic Tank Vertikal (1.5") | V5: Pipa Resapan ke & dari Septic Tank (4") | W5: Pipa Utama 4" vertikal | X5: Pipa Utama 8"
A7: PAH Atap
A8: PAH LT3
A9: PAH LT3
A10: PAH LT2
A11: PAH LT2
A12: PAH LT2
A13: PAH LT1
A14: PAH LT1
A15: PAH LT1
A16: PAH LT1
A17: PAH Basement
A18: PAH Basement
... A50: Pipa Vent Basement
A53: TOTAL (mm' net) | C53: =SUM(C6:C52) -> 0 | D53: =SUM(D6:D52) -> 0 | E53: =SUM(E6:E52) -> 0 | F53: =SUM(F6:F52) -> 0 | G53: =SUM(G6:G52) -> 0 | H53: =SUM(H6:H52) -> 0 | I53: =SUM(I6:I52) -> 0 | K53: =SUM(K6:K52) -> 0 | L53: =SUM(L6:L52) -> 0 | M53: =SUM(M6:M52) -> 0 | N53: =SUM(N6:N52) -> 0 | O53: =SUM(O6:O52) -> 0 | P53: =SUM(P6:P52) -> 0 | R53: =SUM(R6:R52) -> 0 | S53: =SUM(S6:S52) -> 0 | T53: =SUM(T6:T52) -> 0 | U53: =SUM(U6:U52) -> 0 | V53: =SUM(V6:V52) -> 0 | W53: =SUM(W6:W52) -> 0 | X53: =SUM(X6:X52) -> 0
A55: TOTAL (m' dibulatkan) | C55: =ROUNDUP(C53/4000,0)*4 -> 0 | D55: =ROUNDUP(D53/4000,0)*4 -> 0 | E55: =ROUNDUP(E53/4000,0)*4 -> 0 | F55: =ROUNDUP(F53/4000,0)*4 -> 0 | G55: =ROUNDUP(G53/4000,0)*4 -> 0 | H55: =ROUNDUP(H53/4000,0)*4 -> 0 | I55: =ROUNDUP(I53/4000,0)*4 -> 0 | K55: =ROUNDUP(K53/4000,0)*4 -> 0 | L55: =ROUNDUP(L53/4000,0)*4 -> 0 | M55: =ROUNDUP(M53/4000,0)*4 -> 0 | N55: =ROUNDUP(N53/4000,0)*4 -> 0 | O55: =ROUNDUP(O53/4000,0)*4 -> 0 | P55: =ROUNDUP(P53/4000,0)*4 -> 0 | R55: =ROUNDUP(R53/4000,0)*4 -> 0 | S55: =ROUNDUP(S53/4000,0)*4 -> 0 | T55: =ROUNDUP(T53/4000,0)*4 -> 0 | U55: =ROUNDUP(U53/4000,0)*4 -> 0 | V55: =ROUNDUP(V53/4000,0)*4 -> 0 | W55: =ROUNDUP(W53/4000,0)*4 -> 0 | X55: =ROUNDUP(X53/4000,0)*4 -> 0
C57: m' | D57: btg | E57: Sisa
B58: 1,5" | C58: =K55+L55+T55+U55 -> 0 | D58: =C58/4 -> 0 | E58: =D58-SUM($F58:$XFD58) -> 0
B59: 2"
B60: 2,5" | C60: =C55+D55 -> 0 | D60: =C60/4 -> 0 | E60: =D60-SUM($F60:$XFD60) -> 0
B61: 3" | C61: =+M55+N55+O55+P55+R55+S55 -> 0 | D61: =C61/4 -> 0 | E61: =D61-SUM($F61:$XFD61) -> 0
B62: 4" | C62: =+E55+F55+V55+W55 -> 0 | D62: =C62/4 -> 0 | E62: =D62-SUM($F62:$XFD62) -> 0
B63: 6" | C63: =G55+H55 -> 0 | D63: =C63/4 -> 0 | E63: =D63-SUM($F63:$XFD63) -> 0
B64: 8" | C64: =+I55 -> 0 | D64: =C64/4 -> 0 | E64: =D64-SUM($F64:$XFD64) -> 0

Sheet Upah
A4: No. | B4: P E K E R J A A N | C4: SAT | D4: UPAH NET | F4: UPAH MANDOR (LT. DASAR) | H4: UPAH TATA
D5: Rp. | F5: Rp.
A7: 1 | B7: Pekerjaan Galian manual | C7: m3
A8: =1+A7 -> 2 | B8: Pekerjaan urugan kembali | C8: m3
A9: =1+A8 -> 3 | B9: Pekerjaan Urugan Pasir | C9: m3
A10: =1+A9 -> 4 | B10: Pekerjaan urugan sirtu | C10: m3
A11: =1+A10 -> 5 | B11: Pemadatan tanah | C11: m2
A12: =1+A11 -> 6 | B12: Bobok kepala tiang diameter 50 cm | C12: titik
A13: =1+A12 -> 7 | B13: Bobok kepala mini pile 25 cm x 25 cm | C13: titik
A14: =1+A13 -> 8 | B14: Lantai Kerja tebal : 7 cm | C14: m3 | D14: =F14 -> 600000 | F14: 600000 | H14: 300000
A15: =1+A14 -> 9 | B15: Lantai kerja plastic sheet | C15: m2 | D15: =F15 -> 0
A16: =1+A15 -> 10 | B16: Pasang Batu Kali | C16: m3 | D16: 100000
A17: =1+A16 -> 11 | B17: Cor Beton Manual | C17: m3 | D17: =F17 -> 100000 | F17: 100000 | H17: 75000
A18: =1+A17 -> 12 | B18: Cor Beton dengan site mix | C18: m3 | D18: =F18 -> 0
A19: =1+A18 -> 13 | B19: Cor Beton Dengan Tower Crane (komponen struktur vertikal) | C19: m3 | D19: =F19 -> 0
A20: =1+A19 -> 14 | B20: Cor Beton Dengan Concrete Pump | C20: m3 | D20: =F20 -> 250000 | F20: 250000 | H20: 55000
B21: Vibrator | C21: m3 | D21: =F21 -> 15000 | F21: 15000
B22: Sewa concrete pump | C22: m3 | D22: =F22 -> 85000 | F22: 85000
A23: =1+A20 -> 15 | B23: Pasang besi dengan Tower Crane | C23: kg | D23: =F23 -> 0
A24: =1+A23 -> 16 | B24: Pasang besi manual | C24: kg | D24: =F24 -> 2500 | F24: 2500
A25: =1+A24 -> 17 | B25: Pasang Wiremesh | C25: m2 | D25: =F25 -> 8000 | F25: 8000
A26: =1+A25 -> 18 | B26: Pasang bekisting batako posisi tidur | C26: m2 | D26: =F26 -> 0
A27: =1+A26 -> 19 | B27: Pasang bekisting batako posisi berdiri | C27: m2 | D27: =F27 -> 0
A28: =1+A27 -> 20 | B28: Ongkos pasang bekisting | C28: m2 | D28: =F28 -> 60000 | F28: 60000
B29: Ongkos bongkar bekisting | C29: m2 | D29: =F29 -> 25000 | F29: 25000
B30: Ongkos pasang bekisting bondek | C30: m2 | D30: =F30 -> 85000 | F30: 85000
A31: =1+A90 -> 1 | B31: Plesteran Semen Instant | C31: m2 | D31: =F31 -> 35000 | F31: 35000
A32: =1+A31 -> 2 | B32: Plesteran Konvensional | C32: m2 | D32: =F32 -> 0
A33: =1+A32 -> 3 | B33: Acian Semen Instant | C33: m2 | D33: =F33 -> 25000 | F33: 25000
A34: =1+A33 -> 4 | B34: Acian Semen Konvensional | C34: m2 | D34: =F34 -> 0
A35: =1+A34 -> 5 | B35: Benangan | C35: m | D35: =F35 -> 20000 | F35: 20000
A36: =1+A35 -> 6 | B36: Pasang Kolom Praktis | C36: m2 | D36: =F36 -> 40000 | F36: 40000
A37: =1+A36 -> 7 | B37: Screed Lantai | C37: m2
A38: =1+A37 -> 8 | B38: Pasang Keramik dan HT / GT lantai | C38: m2
A39: =1+A38 -> 9 | B39: Pasang Keramik lantai bermotif (susun bata / herringbone / dsb) | C39: m2
A40: =1+A39 -> 10 | B40: Pasang Keramik dan HT / GT dinding | C40: m2
A41: =1+A40 -> 11 | B41: Pasang Skirting Keramik | C41: m
A42: =1+A41 -> 12 | B42: Pasang Skirting Homogenous Tile | C42: m
A43: =1+A42 -> 13 | B43: Pasang Stepnosing | C43: m
A44: =1+A43 -> 14 | B44: Finish Floor Hardener | C44: m2
...

Sheet Material
A1: Tanggal | C1: :
A2: Proyek | C2: :
A3: Lokasi | C3: :
A5: No. | B5: M A T E R I A L S | E5: PRODUK / MODEL / TIPE | F5: SAT | G5: HARGA NET
G6: Rp.
A8: 1 | B8: Pasir Pasang | E8: ex : Lumajang | F8: m3 | G8: =ROUNDUP(2100000/6,-4) -> 350000 | H8: 2,1jt/rit
B9: Pasir Pasang | E9: ex : Kertosono | F9: m3 | G9: =ROUNDUP(1300000/6,-4) -> 220000 | H9: 1,3jt/rit
A10: =+A17+1 -> 3 | B10: Split 1:1 | E10: ex : lokal | F10: m3 | G10: 275000 | I10: harga beton Jayamix BDG H-16 SEBELUM PPN:
A11: =+A27+1 -> 14 | B11: Readymix K-350 (fc' 35 Mpa) | E11: slump 18 ± 2 cm, Non Fly Ash, Self-Consolidating Concrete (SCC) atau ditambah additive hyperflow | F11: m3 | G11: =1050000*1.11 -> 1165500 | I11: K-300 (fc'25) | J11: 785000
A12: =+A11+1 -> 15 | B12: Readymix K-350 (fc' 35 Mpa) | E12: slump 18 ± 2 cm, Non Fly Ash, split 1:1 | F12: m3 | G12: =1050000*1.11 -> 1165500 | I12: K-350 (fc'30) | J12: 875000
B13: Readymix K-350 (fc' 30 Mpa) | E13: slump 18 ± 2 cm, Non Fly Ash, split 1:1 | F13: m3 | G13: =1050000*1.11 -> 1165500 | I13: K-400 (fc'32,5) | J13: 840000
A14: =+A20+1 -> 7 | B14: Semen PC | E14: ex : Semen Gresik / Holcim / Tiga Roda @ 50 kg | F14: sak | G14: 65000 | I14: K-450 (fc'35) | J14: 935000
B15: Bentonite | F15: kg | G15: 3000 | I15: additive hyperflow | J15: 50000
B16: Bahan bakar molen | F16: ltr | G16: 13000
A17: =+A8+1 -> 2 | B17: Pasir Urug | E17: ex : lokal | F17: m3 | G17: 175000
A18: =+A10+1 -> 4 | B18: Sirtu | E18: ex : lokal | F18: m3
A19: =A18+1 -> 5 | B19: Batu kali | E19: ex : lokal | F19: m3 | G19: 250000
A20: =A19+1 -> 6 | B20: Batako tebal 10 cm | E20: ex : lokal | F20: bh | G20: 4500
B21: Air kerja | F21: m3 | G21: 40000
A22: =+A14+1 -> 8 | B22: Readymix B0 | E22: slump 12 ± 2 cm, FA max 10% | F22: m3
A23: =+A22+1 -> 9 | B23: Readymix fc' 35 Mpa (khusus Raft) | F23: m3
A24: =+A23+1 -> 10 | B24: Readymix fc' 25 MPa | F24: m3
A25: =+A24+1 -> 11 | B25: Readymix fc' 30 MPa | F25: m3
A26: =+A25+1 -> 12 | B26: Readymix fc' 35 MPa | F26: m3
A27: =+A26+1 -> 13 | B27: Readymix fc' 40 MPa | F27: m3
A28: =+A12+1 -> 16 | B28: Readymix K-250 | F28: m3
A29: =+A28+1 -> 17 | B29: Additive | E29: ex : LN | F29: ltr
A30: =+A29+1 -> 18 | B30: Curing Compound | E30: ex : Masterkure 128 ex. BASF | F30: ltr
A31: =+A30+1 -> 19 | B31: Form oil | F31: ltr | G31: 27500 | J31: Wire Mesh | K31: 10000 | L31: /kg
A32: =+A31+1 -> 20 | B32: Bonding Agent | E32: ex : Sikabond | F32: ltr
A33: =+A32+1 -> 21 | B33: Besi beton BJTP U24 & BJTD U40 | E33: standard SNI | F33: kg | G33: 9500 | I33: dia | J33: jarak | K33: P | L33: L | M33: brt/m2
A34: =+A33+1 -> 22 | B34: Wiremesh M-10 | E34: ex. BHP / Lion | F34: m2 | G34: =M34*$K$31 -> 85135.714 | I34: 10 | J34: 150 | K34: 5.4 | L34: 2.1 | M34: =(0.006165*I34*I34)*(K34*ROUND(L34/(J34/1000)+1,0)+L34*ROUND(K34/(J34/1000),0))/(K34*L34) -> 8.5135714
A35: =+A34+1 -> 23 | B35: Wiremesh M-9 | E35: ex. BHP / Lion | F35: m2 | G35: =M35*$K$31 -> 68959.929 | H35: =778000/(2.1*5.4) -> 68606.702 | I35: 9 | J35: 150 | K35: 5.4 | L35: 2.1 | M35: =(0.006165*I35*I35)*(K35*ROUND(L35/(J35/1000)+1,0)+L35*ROUND(K35/(J35/1000),0))/(K35*L35) -> 6.8959929
A36: =+A35+1 -> 24 | B36: Wiremesh M-8 | E36: ex. BHP / Lion | F36: m2 | G36: =M36*$K$31 -> 54486.857 | H36: =549000/(2.1*5.4) -> 48412.698 | I36: 8 | J36: 150 | K36: 5.4 | L36: 2.1 | M36: =(0.006165*I36*I36)*(K36*ROUND(L36/(J36/1000)+1,0)+L36*ROUND(K36/(J36/1000),0))/(K36*L36) -> 5.4486857
A37: =+A36+1 -> 25 | B37: Wiremesh M-7 | E37: ex. BHP / Lion | F37: m2 | G37: =M37*$K$31 -> 41716.5 | H37: =419000/(2.1*5.4) -> 36948.854 | I37: 7 | J37: 150 | K37: 5.4 | L37: 2.1 | M37: =(0.006165*I37*I37)*(K37*ROUND(L37/(J37/1000)+1,0)+L37*ROUND(K37/(J37/1000),0))/(K37*L37) -> 4.17165
A38: =+A37+1 -> 26 | B38: Wiremesh M-5 | E38: ex. BHP / Lion | F38: m2 | G38: =M38*$K$31 -> 30648.857 | I38: 6 | J38: 150 | K38: 5.4 | L38: 2.1 | M38: =(0.006165*I38*I38)*(K38*ROUND(L38/(J38/1000)+1,0)+L38*ROUND(K38/(J38/1000),0))/(K38*L38) -> 3.0648857
A39: =+A38+1 -> 27 | B39: Kawat beton | E39: ex : lokal | F39: kg | G39: 17500
B41: Profil baja standar | F41: kg | G41: 30000
B42: Profil baja besar | F42: kg | G42: 32500
B43: Profil baja khusus (misal: gording) | F43: kg | G43: 27500
...

Sheet Hitungan Tangga
D1: KAIT TULANGAN UTAMA | E1: = | F1: 12 | G1: D
D2: BALOK BORDES 200/400 | E2: DIAMETER | F2: PANJANG (m) | G2: PENJANGKARAN | H2: TOTAL | I2: BERAT | J2: JUMLAH | K2: BERAT
D3: TUL ATAS | E3: 13 | F3: =7540/2/1000 -> 3.77 | G3: =2*$F$1*E3/1000 -> 0.312 | H3: =F3+G3 -> 4.082 | I3: =0.006165*E3^2*F3 -> 3.9279065 | J3: 3 | K3: =J3*I3*G3 -> 3.6765204
D4: TUL PEMINGGANG | E4: 0 | F4: 0 | G4: =2*$F$1*E4/1000 -> 0 | H4: =F4+G4 -> 0 | I4: =0.006165*E4^2 -> 0 | J4: 0 | K4: =J4*I4*G4 -> 0
D5: TUL BAWAH | E5: 13 | F5: =7540/2/1000 -> 3.77 | G5: =2*$F$1*E5/1000 -> 0.312 | H5: =F5+G5 -> 4.082 | I5: =0.006165*E5^2*F5 -> 3.9279065 | J5: 3 | K5: =J5*I5*G5 -> 3.6765204
D6: SENGKANG | E6: 10 | F6: =(2*(400+200)-40*4)/1000 -> 1.04 | G6: =MAX(6*E6,75)/1000 -> 0.075 | H6: =F6+G6 -> 1.115 | I6: =0.006165*E6^2 -> 0.6165 | J6: =ROUNDUP(2100/150,0) -> 14 | K6: =J6*I6*G6 -> 0.647325
J7: BERAT TOTAL | K7: =SUM(K3:K6) -> 8.0003659
A10: Tangga carport | B10: LUAS (m2) | C10: LEBAR (m) | D10: VOL.BETON (m3) | E10: BERAT BESI (KG) | F10: Bekisting m2 | G10: ARAH Y | L10: ARAH X
G11: PANJANG | H11: TULANGAN | I11: JUMLAH | J11: BERAT/PCS | K11: BERAT TOTAL | L11: PANJANG | M11: PENJANGKARAN | N11: TOTAL | O11: TULANGAN | P11: JUMLAH | Q11: BERAT/PCS | R11: BERAT TOTAL
A12: TANGGA | B12: =41.2407688232/5^2 -> 1.6496308 | C12: 2.1 | D12: =B12*C12 -> 3.4642246 | E12: =(SUM(K12:K13)+SUM(R12:R13)) -> 323.84168 | F12: =P13*(145+350)/5/1000*C12+2*B12+38.043/5*C12 -> 23.435322 | G12: =(6.669+52.895+45.379+15.36)/5 -> 24.0606 | H12: 10 | I12: =ROUNDUP(2100/150,0) -> 14 | J12: =0.006165*H12^2 -> 0.6165 | K12: =J12*I12*G12 -> 207.66704 | L12: =(2100-2*40)/1000/5 -> 0.404 | M12: =2*$F$1*O12/1000 -> 0.24 | N12: =L12+M12 -> 0.644 | O12: 10 | P12: 100 | Q12: =0.006165*O12^2 -> 0.6165 | R12: =N12*Q12*P12 -> 39.7026
G13: =4.134*P13/5 -> 16.536 | H13: 8 | I13: =ROUNDUP(2100/200,0) -> 11 | J13: =0.006165*H13^2 -> 0.39456 | K13: =J13*I13*G13 -> 71.768886 | L13: =(2100-2*40)/1000/5 -> 0.404 | M13: =2*$F$1*O13/1000 -> 0.192 | N13: =L13+M13 -> 0.596 | O13: 8 | P13: 20 | Q13: =0.006165*O13^2 -> 0.39456 | R13: =N13*Q13*P13 -> 4.7031552
A14: BORDES | B14: =30.386567/2^2 -> 7.5966417 | C14: 0.15 | D14: =B14*C14 -> 1.1394963 | E14: =(SUM(K14:K14)+SUM(R14:R14)) -> 41.57676 | F14: =6.909*C14+B14 -> 8.6329918 | G14: =(2.4*3/4)/2 -> 0.9 | H14: 10 | I14: =ROUNDUP(2400/150,0) -> 16 | J14: =0.006165*H14^2 -> 0.6165 | K14: =J14*I14*G14 -> 8.8776 | L14: =(4.8*3/4)/2 -> 1.8 | M14: =2*$F$1*O14/1000 -> 0.24 | N14: =L14+M14 -> 2.04 | O14: 10 | P14: 26 | Q14: =0.006165*O14^2 -> 0.6165 | R14: =N14*Q14*P14 -> 32.69916
A15: BALOK BORDES 200/400 | B15: =400*200/1000000 -> 0.08 | C15: =7540/2/1000 -> 3.77 | D15: =B15*C15 -> 0.3016 | E15: =K7 -> 8.0003659 | F15: =0.4*0.2*2+(0.4+0.2)*7.537+0.25*6.909 -> 6.40945
C17: total | D17: =SUM(D12:D15) -> 4.9053208 | E17: =SUM(E12:E15) -> 373.41881 | F17: =SUM(F12:F16) -> 38.477763
D20: BALOK BORDES 200/450 | E20: DIAMETER | G20: PANJANG (m) | H20: PENJANGKARAN | I20: TOTAL | J20: BERAT | K20: JUMLAH | L20: BERAT
D21: TUL ATAS | E21: 13 | G21: =1650/1000 -> 1.65 | H21: =2*$F$1*E21/1000 -> 0.312 | I21: =G21+H21 -> 1.962 | J21: =0.006165*E21^2*G21 -> 1.7191102 | K21: 5 | L21: =K21*J21*H21 -> 2.681812
D22: TUL PEMINGGANG | E22: 8 | G22: =1650/1000 -> 1.65 | H22: =2*$F$1*E22/1000 -> 0.192 | I22: =G22+H22 -> 1.842 | J22: =0.006165*E22^2*G22 -> 0.651024 | K22: 2 | L22: =K22*J22*H22 -> 0.24999322
D23: TUL BAWAH | E23: 13 | G23: =1650/1000 -> 1.65 | H23: =2*$F$1*E23/1000 -> 0.312 | I23: =G23+H23 -> 1.962 | J23: =0.006165*E23^2*G23 -> 1.7191102 | K23: 4 | L23: =K23*J23*H23 -> 2.1454496
D24: SENGKANG | E24: 10 | G24: =(2*(450+200)-40*4)/1000 -> 1.14 | H24: =MAX(6*E24,75)/1000 -> 0.075 | I24: =G24+H24 -> 1.215 | J24: =0.006165*E24^2*G24 -> 0.70281 | K24: =ROUNDUP(1650/100,0) -> 17 | L24: =K24*J24*H24 -> 0.89608275
K25: BERAT TOTAL | L25: =SUM(L21:L24) -> 5.9733375
A27: Tangga utama | B27: LUAS | C27: LEBAR | D27: VOL.BETON | E27: BERAT BESI (KG) | F27: Bekisting | G27: ARAH Y | L27: ARAH X
G28: PANJANG | H28: TULANGAN | I28: JUMLAH | J28: BERAT/PCS | K28: BERAT TOTAL | L28: PANJANG | M28: PENJANGKARAN | N28: TOTAL | O28: TULANGAN | P28: JUMLAH | Q28: BERAT/PCS | R28: BERAT TOTAL
A29: Pot 3a | B29: =26.855736/5^2 -> 1.0742294 | C29: 1.65 | D29: =B29*C29 -> 1.7724786 | E29: =(SUM(K29:K30)+SUM(R29:R30)) -> 299.21232 | G29: =(33.214+8.717+32.044+7.629)/5 -> 16.3208 | H29: 13 | I29: =ROUNDUP(1650/150,0) -> 11 | J29: =0.006165*H29^2 -> 1.041885 | K29: =J29*I29*G29 -> 187.04836 | L29: =(1650-2*40)/1000 -> 1.57 | M29: =2*$F$1*O29/1000 -> 0.24 | N29: =L29+M29 -> 1.81 | O29: 10 | P29: 58 | Q29: =0.006165*O29^2 -> 0.6165 | R29: =N29*Q29*P29 -> 64.72017
G30: =4.588*P30/5 -> 11.0112 | H30: 8 | I30: =ROUNDUP(1650/200,0) -> 9 | J30: =0.006165*H30^2 -> 0.39456 | K30: =J30*I30*G30 -> 39.101212 | L30: =(1650-2*40)/1000 -> 1.57 | M30: =2*$F$1*O30/1000 -> 0.192 | N30: =L30+M30 -> 1.762 | O30: 8 | P30: 12 | Q30: =0.006165*O30^2 -> 0.39456 | R30: =N30*Q30*P30 -> 8.3425766
A31: Pot 3b | B31: =26.185062/5^2 -> 1.0474025 | C31: 1.65 | D31: =B31*C31 -> 1.7282141 | E31: =(SUM(K31:K32)+SUM(R31:R32))+$L$25 -> 246.31212 | G31: =(13.899+15.714+23.257+14.643+11.98)/5 -> 15.8986 | H31: 13 | I31: =ROUNDUP(1650/150,0) -> 11 | J31: =0.006165*H31^2 -> 1.041885 | K31: =J31*I31*G31 -> 182.20964 | L31: =(1650-2*40)/1000 -> 1.57 | M31: =2*$F$1*O31/1000 -> 0.24 | N31: =L31+M31 -> 1.81 | O31: 10 | P31: 36 | Q31: =0.006165*O31^2 -> 0.6165 | R31: =N31*Q31*P31 -> 40.17114
G32: =4.588*P32/5 -> 4.588 | H32: 8 | I32: =ROUNDUP(1500/200,0) -> 8 | J32: =0.006165*H32^2 -> 0.39456 | K32: =J32*I32*G32 -> 14.48193 | L32: =(1650-2*40)/1000 -> 1.57 | M32: =2*$F$1*O32/1000 -> 0.192 | N32: =L32+M32 -> 1.762 | O32: 8 | P32: 5 | Q32: =0.006165*O32^2 -> 0.39456 | R32: =N32*Q32*P32 -> 3.4760736
A33: Pot 3c | B33: =26.101329/5^2 -> 1.0440532 | C33: 1.65 | D33: =B33*C33 -> 1.7226877 | E33: =(SUM(K33:K34)+SUM(R33:R34)) -> 311.4016 | G33: =(11.149+13.692+30.997+26.351+8.682)/5 -> 18.1742 | H33: 13 | I33: =ROUNDUP(1650/150,0) -> 11 | J33: =0.006165*H33^2 -> 1.041885 | K33: =J33*I33*G33 -> 208.28969 | L33: =(1650-2*40)/1000 -> 1.57 | M33: =2*$F$1*O33/1000 -> 0.24 | N33: =L33+M33 -> 1.81 | O33: 10 | P33: 57 | Q33: =0.006165*O33^2 -> 0.6165 | R33: =N33*Q33*P33 -> 63.604305
G34: =4.588*P34/5 -> 10.0936 | H34: 8 | I34: =ROUNDUP(1500/200,0) -> 8 | J34: =0.006165*H34^2 -> 0.39456 | K34: =J34*I34*G34 -> 31.860247 | L34: =(1650-2*40)/1000 -> 1.57 | M34: =2*$F$1*O34/1000 -> 0.192 | N34: =L34+M34 -> 1.762 | O34: 8 | P34: 11 | Q34: =0.006165*O34^2 -> 0.39456 | R34: =N34*Q34*P34 -> 7.6473619
B35: total | C35: Utama | D35: =SUM(D29:D34) -> 5.2233804 | E35: =SUM(E29:E34) -> 856.92605
D38: BALOK BORDES 200/450 | E38: DIAMETER | G38: PANJANG (m) | H38: PENJANGKARAN | I38: TOTAL | J38: BERAT | K38: JUMLAH | L38: BERAT
D39: TUL ATAS | E39: 13 | G39: =950/1000 -> 0.95 | H39: =2*$F$1*E39/1000 -> 0.312 | I39: =G39+H39 -> 1.262 | J39: =0.006165*E39^2*G39 -> 0.98979075 | K39: 3 | L39: =K39*J39*H39 -> 0.92644414
D40: TUL PEMINGGANG | E40: 8 | G40: =950/1000 -> 0.95 | H40: =2*$F$1*E40/1000 -> 0.192 | I40: =G40+H40 -> 1.142 | J40: =0.006165*E40^2*G40 -> 0.374832 | K40: 2 | L40: =K40*J40*H40 -> 0.14393549
D41: TUL BAWAH | E41: 13 | G41: =950/1000 -> 0.95 | H41: =2*$F$1*E41/1000 -> 0.312 | I41: =G41+H41 -> 1.262 | J41: =0.006165*E41^2*G41 -> 0.98979075 | K41: 3 | L41: =K41*J41*H41 -> 0.92644414
D42: SENGKANG | E42: 10 | G42: =(2*(450+200)-40*4)/1000 -> 1.14 | H42: =MAX(6*E42,75)/1000 -> 0.075 | I42: =G42+H42 -> 1.215 | J42: =0.006165*E42^2*G42 -> 0.70281 | K42: =ROUNDUP(950/100,0) -> 10 | L42: =K42*J42*H42 -> 0.5271075
K43: BERAT TOTAL | L43: =SUM(L39:L42) -> 2.5239313
D45: BALOK BORDES 200/700 | E45: DIAMETER | G45: PANJANG (m) | H45: PENJANGKARAN | I45: TOTAL | J45: BERAT | K45: JUMLAH | L45: BERAT
D46: TUL ATAS | E46: 16 | G46: =950/1000 -> 0.95 | H46: =2*$F$1*E46/1000 -> 0.384 | I46: =G46+H46 -> 1.334 | J46: =0.006165*E46^2*G46 -> 1.499328 | K46: 3 | L46: =K46*J46*H46 -> 1.7272259
D47: TUL PEMINGGANG | E47: 10 | G47: =950/1000 -> 0.95 | H47: =2*$F$1*E47/1000 -> 0.24 | I47: =G47+H47 -> 1.19 | J47: =0.006165*E47^2*G47 -> 0.585675 | K47: 2 | L47: =K47*J47*H47 -> 0.281124
D48: TUL BAWAH | E48: 16 | G48: =950/1000 -> 0.95 | H48: =2*$F$1*E48/1000 -> 0.384 | I48: =G48+H48 -> 1.334 | J48: =0.006165*E48^2*G48 -> 1.499328 | K48: 3 | L48: =K48*J48*H48 -> 1.7272259
D49: SENGKANG | E49: 10 | G49: =(2*(700+200)-40*4)/1000 -> 1.64 | H49: =MAX(6*E49,75)/1000 -> 0.075 | I49: =G49+H49 -> 1.715 | J49: =0.006165*E49^2*G49 -> 1.01106 | K49: =ROUNDUP(950/100,0) -> 10 | L49: =K49*J49*H49 -> 0.758295
...

Sheet COVER
A1: Estimasi Biaya Pembangunan Fisik Rumah Tinggal
A2: Lokasi | B2: ='REKAP RAB'!B2 -> : Citraland Emerald Mansion
A3: Pemilik | B3: ='REKAP RAB'!B3 -> : Ms. Ernawati
A4: Tanggal | B4: ='REKAP RAB'!B4 -> : Januari 2026
B7: REKAPITULASI TOTAL:
E8: PENAWARAN | H8: NETTO
A9: A | B9: ='REKAP RAB'!B9 -> Pekerjaan Fisik Bangunan Utama | E9: ='REKAP RAB'!F9 -> 4.5919993e+09 | H9: ='REKAP RAB'!O39 -> 3.9874836e+09
A10: B | B10: ='REKAP RAB'!B10 -> Pekerjaan Persiapan, Cut & Fill, dan Anti Rayap | E10: ='REKAP RAB'!F10 -> 4.6681389e+08 | H10: ='REKAP RAB'!O67 -> 4.3209009e+08
F11: + | I11: +
C12: GRAND TOTAL | E12: =E9+E10 -> 5.0588132e+09 | H12: =H9+H10 -> 4.4195737e+09
A14: Luas : | B14: ='REKAP RAB'!J13 -> - Lantai 1 | C14: ='REKAP RAB'!K13 -> 288.09378
B15: ='REKAP RAB'!J14 -> - Lantai 2 | C15: ='REKAP RAB'!K14 -> 185.72976
B16: ='REKAP RAB'!J15 -> - Lantai 3 | C16: ='REKAP RAB'!K15 -> 192.46181
B17: ='REKAP RAB'!J16 -> - Lantai Atap | C17: ='REKAP RAB'!K16 -> 132.48145
B19: Total Luas Bangunan | C19: =SUM(C14:C18) -> 798.7668 | D19: m2
B21: Harga Bangunan Fisik | C21: =SUM(E9:E9)/C19 -> 5748861 | D21: /m2 | E21: (TOTAL A)
B22: Harga Bangunan Fisik NETTO | C22: =SUM(H9:H9)/C19 -> 4992049.8 | D22: /m2 | E22: (TOTAL A)
B24: Simpanan profit FISIK | C24: =C21/C22-1 -> 0.15160329 | E24: (belum termasuk potongan PPh)
B28: Komposisi RAB (netto):
B30: Material
B31: Upah | E31: (borongan mandor)
B32: Peralatan | E32: (scaffolding, concrete pump, dsb)
B33: Subkon | E33: (cut & fill, pancang, baja, septic tank)
B34: Preliminary
B36: TOTAL NETTO

Sheet REKAP RAB
A1: Estimasi Biaya Pembangunan Fisik Rumah Tinggal
A2: Lokasi | B2: : Citraland Emerald Mansion | N2: Pek. Tanah | O2: 1.1 | R2: Benangan | S2: A
A3: Pemilik | B3: : Ms. Ernawati | J3: FAKTOR KALI VOLUME (BETON, TANAH, DAN DINDING) | K3: 1 | N3: Pek. Tiang Pancang | O3: 1.08 | R3: Screed | S3: A
A4: Tanggal | B4: : Januari 2026 | J4: (spare untuk nego. Yang dikalikan faktor ini: balok, kolom, pas. Dinding, gali, urug) | N4: Pek. Pondasi Strauss | O4: a
N5: Pek. Beton Borongan | O5: 1.15
N6: Pek. Baja & Atap | O6: 1.15
B7: REKAPITULASI TOTAL: | N7: Pek. Pasangan Dinding | O7: 1.15
J8: Catatan : | N8: Pek. Saluran | O8: 1.13
A9: A | B9: Pekerjaan Fisik Bangunan Utama | F9: ='REKAP RAB'!F39 -> 4.5919993e+09
A10: B | B10: Pekerjaan Persiapan, Cut & Fill, dan Anti Rayap | F10: =F67 -> 4.6681389e+08 | G10: +
E12: GRAND TOTAL | F12: =F9+F10 -> 5.0588132e+09 | J12: Luas :
J13: - Lantai 1 | K13: ='REKAP Plat'!F18 -> 288.09378
J14: - Lantai 2 | K14: ='REKAP Plat'!F36 -> 185.72976
J15: - Lantai 3 | K15: ='REKAP Plat'!F44 -> 192.46181
J16: - Lantai Atap | K16: ='REKAP Plat'!F51+(188.091565-27.826308)*0.7 -> 132.48145
L18: m2
K19: =SUM(K13:K18) -> 798.7668 | L19: m2 | O19: =SUM(O39,O67) -> 4.4195737e+09
I21: 2 | J21: Harga Bangunan Fisik | K21: =F9/K19 -> 5748861 | L21: /m2 | O21: =O39/K19 -> 4992049.8 | P21: /m2 | Q21: =K21/O21-1 -> 0.15160329
J22: Harga Bangunan Fisik Total (incl. pancang, cut & fill, anti rayap) | K22: =SUM(F9:F9)/K19 -> 5748861 | L22: /m2 | O22: =SUM(O39,O67)/K19 -> 5532996.3 | P22: /m2 | Q22: =K22/O22-1 -> 0.039014066
O24: =O23*1.1265*K19 -> 0
K25: Nilai Kontrak (incl. overhead) | L25: Perubahan (+ / -)
B26: REKAPITULASI (A):
B27: Pekerjaan Fisik Bangunan Utama | J27: draft R0 dari Julius | K27: =F12 -> 5.0588132e+09
L28: =K28-K27 -> -5.0588132e+09
A29: I | B29: Pekerjaan Persiapan | F29: ='RAB (A)'!F20 -> 132545000 | L29: =K29-K28 -> 0 | O29: ='RAB (A)'!O20 -> 132545000
A30: II | B30: Pekerjaan Tanah | F30: ='RAB (A)'!F29 -> 1.5220573e+08 | L30: =K30-K29 -> 0 | O30: ='RAB (A)'!O29 -> 1.3661499e+08
A31: III | B31: Pekerjaan Fisik Lantai 1 | F31: ='RAB (A)'!F139 -> 1.1468596e+09 | L31: =K31-K30 -> 0 | O31: ='RAB (A)'!O139 -> 9.681536e+08
A32: IV | B32: Pekerjaan Fisik Lantai 2 | F32: ='RAB (A)'!F172 -> 6.0809407e+08 | L32: =K32-K31 -> 0 | O32: ='RAB (A)'!O172 -> 5.5168903e+08
A33: V | B33: Pekerjaan Fisik Lantai 3 | F33: ='RAB (A)'!F201 -> 5.3502792e+08 | L33: =K33-K32 -> 0 | O33: ='RAB (A)'!O201 -> 4.4016469e+08
A34: VI | B34: Pekerjaan Fisik Lantai Atap | F34: ='RAB (A)'!F219 -> 1.8576073e+08 | L34: =K34-K33 -> 0 | O34: ='RAB (A)'!O219 -> 1.6153107e+08
A35: VII | B35: Pekerjaan Baja dan Penutup Atap | F35: ='RAB (A)'!F237 -> 5.0334171e+08 | L35: =K35-K34 -> 0 | O35: ='RAB (A)'!O237 -> 4.3786101e+08
A36: VIII | B36: Pekerjaan Pasangan Dinding Bata Merah | F36: ='RAB (A)'!F266 -> 1.0683552e+09 | L36: =K36-K35 -> 0 | O36: ='RAB (A)'!O266 -> 9.2900453e+08
A37: IX | B37: Pekerjaan Instalasi Air Kotor & Air Hujan | F37: ='RAB (A)'!F280 -> 2.5980928e+08 | G37: + | L37: =K37-K36 -> 0 | O37: ='RAB (A)'!O280 -> 2.2991972e+08 | P37: +
L38: =K38-K37 -> 0
E39: TOTAL (A): | F39: =SUM(F29:F37) -> 4.5919993e+09 | L39: =K39-K38 -> 0 | O39: =SUM(O29:O37) -> 3.9874836e+09
B40: KETERANGAN : | L40: =K40-#REF! -> #REF!
A41: 1 | B41: Pekerjaan di atas hanya pekerjaan fisik bangunan saja sesuai dengan perincian yang tertulis.
A42: 2 | B42: Belum termasuk pekerjaan:
B43: - Lisplank dan badugan
B44: - Penebalan dinding untuk keperluan finishing
...

Sheet RAB (B)
A1: Estimasi Biaya Pembangunan Fisik Rumah Tinggal
A2: Pekerjaan | B2: : Pekerjaan Persiapan, Cut & Fill, dan Pondasi
A3: Lokasi | B3: ='REKAP RAB'!B2 -> : Citraland Emerald Mansion
A4: Pemilik | B4: ='REKAP RAB'!B3 -> : Ms. Ernawati
A5: Tanggal | B5: ='REKAP RAB'!B4 -> : Januari 2026
R6: Beton | V6: Bekisting | Z6: Besi | AC6: Wire Mesh
A7: NO | B7: URAIAN PEKERJAAN | C7: SAT | D7: VOLUME | E7: HARGA SATUAN | F7: TOTAL HARGA | H7: VOLUME | I7: Material | J7: Upah | K7: Peralatan | L7: Subkon | M7: Prelim | N7: TOTAL HARGA SATUAN | O7: TOTAL HARGA | R7: Material | S7: Upah | T7: Peralatan | V7: Rasio | W7: Material | X7: Peralatan | Z7: Rasio | AA7: Material | AC7: Rasio | AD7: Material | AF7: Harga Jadi MATERIAL / m3 | AG7: Harga Jadi UPAH / m3 | AH7: Harga Jadi PERALATAN / m3 | AJ7: Total Bekisting | AL7: Total Besi
A9: I | B9: PEKERJAAN CUT & FILL
A11: 1 | B11: Cut and fill untuk persiapan pemancangan | C11: ls | D11: =H11 -> 1 | E11: =N11*'REKAP RAB'!$O$2 -> 39537575 | F11: =D11*E11 -> 39537575 | H11: 1 | L11: =((22+1.5)*(20+3)*0.95)*70000 -> 35943250 | N11: =SUM(I11:M11) -> 35943250 | O11: =H11*N11 -> 35943250 | P11: existing + 40cm dari jalan
A12: 2 | B12: Urugan sirtu rata untuk pekerjaan pondasi | C12: ls | D12: =H12 -> 1 | E12: =N12*'REKAP RAB'!$O$2 -> 79075150 | F12: =D12*E12 -> 79075150 | H12: 1 | L12: =((22+1.5)*(20+3)*0.7)*190000 -> 71886500 | N12: =SUM(I12:M12) -> 71886500 | O12: =H12*N12 -> 71886500 | P12: asumsi fill 70 cm (finish +15 cm dari jalan) | AF12: =R12+V12*W12+Z12*AA12 -> 0 | AG12: =S12 -> 0 | AH12: =T12+V12*X12 -> 0
A13: 3 | B13: Mobilisasi / demobilisasi alat+izin masuk | C13: ls | D13: 1 | E13: =N13 -> 10000000 | F13: =D13*E13 -> 10000000 | H13: 1 | L13: 10000000 | N13: =SUM(I13:M13) -> 10000000 | O13: =H13*N13 -> 10000000 | P13: jadi tebal cut 95 Cm, fill 70 cm
A15: Subtotal Pekerjaan Cut & Fill | F15: =SUM(F8:F14) -> 128612725 | O15: =SUM(O8:O14) -> 117829750
A17: II | B17: PEKERJAAN PONDASI
A19: 1 | B19: Mobilisasi / demobilisasi alat+izin masuk | C19: ls | D19: =H19 -> 1 | E19: =N19 -> 15000000 | F19: =D19*E19 -> 15000000 | H19: 1 | L19: =15000000 -> 15000000 | N19: =SUM(I19:M19) -> 15000000 | O19: =H19*N19 -> 15000000 | P19: (pancang + borepile + kolam borepile)
A20: 2 | B20: Mini Pile 20 x 20 cm (asumsi panjang tiang 12 meter) | C20: titik | D20: =H20 -> 74 | E20: =N20*'REKAP RAB'!$O$3 -> 2181816 | F20: =D20*E20 -> 161454384 | H20: ='REKAP-PC'!E22 -> 74 | L20: =((97500+27500)+5000)*1.11*14 -> 2020200 | N20: =SUM(I20:M20) -> 2020200 | O20: =H20*N20 -> 149494800 | P20: 14M | T20: 0
A21: 3 | B21: Kepras mini pile | C21: titik | D21: =H21 -> 74 | E21: =N21*'REKAP RAB'!$O$3 -> 108000 | F21: =D21*E21 -> 7992000 | G21: =74*13 -> 962 | H21: =H20 -> 74 | J21: 100000 | N21: =SUM(I21:M21) -> 100000 | O21: =H21*N21 -> 7400000
A22: 4 | B22: Bored Pile dia 30cm (panjang tiang 12 meter) | C22: titik | D22: =H22 -> 21 | E22: =N22*'REKAP RAB'!$O$3 -> 5264102.1 | F22: =D22*E22 -> 1.1054615e+08 | H22: ='REKAP-PC'!F22 -> 21 | I22: =Analisa!F282 -> 2424168.7 | J22: =Analisa!G282 -> 2450000 | N22: =SUM(I22:M22) -> 4874168.7 | O22: =H22*N22 -> 1.0235754e+08 | P22: 14M
A23: 5 | B23: Bobok bored pile | C23: titik | D23: =H23 -> 21 | E23: =N23*'REKAP RAB'!$O$3 -> 108000 | F23: =D23*E23 -> 2268000 | H23: =H22 -> 21 | J23: 100000 | N23: =SUM(I23:M23) -> 100000 | O23: =H23*N23 -> 2100000
A24: 6 | B24: Buang lumpur bekas galian bored pile | C24: ls | D24: =H24 -> 1 | E24: =N24*'REKAP RAB'!$O$3 -> 20412000 | F24: =D24*E24 -> 20412000 | H24: 1 | J24: =H23*1.5*600000 -> 18900000 | N24: =SUM(I24:M24) -> 18900000 | O24: =H24*N24 -> 18900000
A26: Subtotal Pekerjaan Cut & Fill | F26: =SUM(F16:F25) -> 3.1767253e+08 | O26: =SUM(O16:O25) -> 2.9525234e+08
A28: III | B28: PEKERJAAN ANTI RAYAP
A30: 1 | B30: Anti rayap sistem injeksi tanah | C30: m2 | D30: =H30 -> 440 | E30: =N30*'REKAP RAB'!$O$3 -> 29160 | F30: =D30*E30 -> 12830400 | H30: =22*20 -> 440 | L30: 27000 | N30: =SUM(I30:M30) -> 27000 | O30: =H30*N30 -> 11880000
A31: 2 | B31: Sistem pipa | C31: m2 | D31: =H31 -> 264 | E31: =N31*'REKAP RAB'!$O$3 -> 29160 | F31: =D31*E31 -> 7698240 | H31: =H30*0.6 -> 264 | L31: 27000 | N31: =SUM(I31:M31) -> 27000 | O31: =H31*N31 -> 7128000
A33: Subtotal Pekerjaan Anti Rayap | F33: =SUM(F27:F32) -> 20528640 | O33: =SUM(O27:O32) -> 19008000
R34: =SUMPRODUCT(#REF!,#REF!) -> #REF! | X34: =SUMPRODUCT(#REF!,#REF!,#REF!) -> #REF!
F35: =SUM(F8:F34)/2 -> 4.6681389e+08 | H35: TOTAL | I35: =SUMPRODUCT(H8:H33,I8:I33) -> 50907542 | J35: =SUMPRODUCT(H8:H33,J8:J33) -> 79850000 | K35: =SUMPRODUCT(H8:H33,K8:K33) -> 0 | L35: =SUMPRODUCT(H8:H33,L8:L33) -> 301332550 | M35: =SUMPRODUCT(H8:H33,M8:M33) -> 0 | O35: =SUM(O8:O34)/2 -> 4.3209009e+08 | R35: jatah concrete pump | X35: jatah scaffolding
H36: TOTAL / m2 | I36: =I35/'REKAP RAB'!$K$13 -> 176704.76 | J36: =J35/'REKAP RAB'!$K$13 -> 277166.69 | K36: =K35/'REKAP RAB'!$K$13 -> 0 | L36: =L35/'REKAP RAB'!$K$13 -> 1045953 | M36: =M35/'REKAP RAB'!$K$13 -> 0 | O36: =O35/'REKAP RAB'!$K$19 -> 540946.48

Sheet REKAP BETON BESI BEKISTING
A1: Lantai | B1: Luas Bangunan | C1: Elemen Struktur | D1: Beton | E1: Bekisting | H1: Besi | U1: Rasio per Lantai
E2: Kayu | F2: Lantai Kerja | G2: Bata / Batako | H2: 6 | I2: 8 | J2: 10 | K2: 13 | L2: 16 | M2: 19 | N2: 22 | O2: 25 | P2: 29 | Q2: 32 | S2: TOTAL BESI | U2: Beton (m3/m2) | V2: Bekisting (m2/m3) | W2: Besi (kg/m3)
A5: Lantai Basement | B5: ='REKAP Plat'!F18 -> 288.09378 | C5: Pile cap | D5: ='REKAP-PC'!B22 -> 24.540556 | F5: ='REKAP-PC'!I22 -> 6.5491084 | G5: ='REKAP-PC'!C22 -> 91.046591 | H5: ='REKAP-PC'!J22 -> 0 | I5: ='REKAP-PC'!K22 -> 0 | J5: ='REKAP-PC'!L22 -> 0 | K5: ='REKAP-PC'!M22 -> 1434.9648 | L5: ='REKAP-PC'!N22 -> 1823.2823 | M5: ='REKAP-PC'!O22 -> 273.15917 | N5: ='REKAP-PC'!P22 -> 0 | O5: ='REKAP-PC'!Q22 -> 0 | P5: 0 | Q5: 0 | S5: =SUM(H5:Q5) -> 3531.4063 | V5: =SUM(E5:G5)/D5 -> 3.9769148 | W5: =S5/D5 -> 143.90083
C6: Kolom Lantai Basement | D6: ='Hasil-Kolom'!F165 -> 28.902461 | E6: ='Hasil-Kolom'!G165 -> 388.61904 | I6: ='Hasil-Kolom'!H165 -> 0 | J6: ='Hasil-Kolom'!I165+'Hasil-Kolom'!L165 -> 2736.2721 | K6: ='Hasil-Kolom'!J165+'Hasil-Kolom'!M165 -> 0 | L6: ='Hasil-Kolom'!K165+'Hasil-Kolom'!N165 -> 4392.6838 | M6: ='Hasil-Kolom'!O165 -> 0 | N6: ='Hasil-Kolom'!P165 -> 0 | O6: ='Hasil-Kolom'!Q165 -> 0 | P6: ='Hasil-Kolom'!R165 -> 0 | S6: =SUM(H6:Q6) -> 7128.9559 | V6: =SUM(E6:G6)/D6 -> 13.445881 | W6: =S6/D6 -> 246.65567
C7: Balok Lantai Basement | D7: ='REKAP Balok'!G281 -> 32.3541 | E7: ='REKAP Balok'!H281 -> 300.411 | F7: ='REKAP Balok'!J281 -> 9.1139 | H7: ='REKAP Balok'!L281 -> 0 | I7: ='REKAP Balok'!M281 -> 1110.134 | J7: ='REKAP Balok'!N281 -> 495.60509 | K7: ='REKAP Balok'!O281 -> 1121.8203 | L7: ='REKAP Balok'!P281 -> 3096.1041 | M7: ='REKAP Balok'!Q281 -> 0 | N7: ='REKAP Balok'!R281 -> 0 | O7: ='REKAP Balok'!S281 -> 0 | P7: ='REKAP Balok'!T281 -> 0 | Q7: 0 | S7: =SUM(H7:Q7) -> 5823.6635 | V7: =SUM(E7:G7)/D7 -> 9.5667906 | W7: =S7/D7 -> 179.9977
C8: Retaining wall | D8: =SUM('Retaining Wall'!C162) -> 8.5733438 | E8: =SUM('Retaining Wall'!D162) -> 114.31125 | I8: =SUM('Retaining Wall'!E162) -> 0 | J8: =SUM('Retaining Wall'!F162) -> 1424.2568 | K8: =SUM('Retaining Wall'!G162) -> 0 | L8: =SUM('Retaining Wall'!H162) -> 0 | M8: =SUM('Retaining Wall'!I162) -> 0 | S8: =SUM(H8:Q8) -> 1424.2568 | V8: =SUM(E8:G8)/D8 -> 13.333333 | W8: =S8/D8 -> 166.12617
C9: Plat Lantai Bangunan | D9: ='REKAP Plat'!G18 -> 51.904365 | E9: ='REKAP Plat'!I18 -> 42.014415 | F9: ='REKAP Plat'!H18 -> 16.891977 | H9: 0 | I9: ='REKAP Plat'!N18 -> 0 | J9: ='REKAP Plat'!O18 -> 5672.7308 | K9: ='REKAP Plat'!P18 -> 0 | L9: ='REKAP Plat'!Q18 -> 0 | M9: ='REKAP Plat'!R18 -> 0 | N9: 0 | O9: 0 | P9: 0 | Q9: 0 | S9: =SUM(H9:Q9) -> 5672.7308 | V9: =SUM(E9:G9)/D9 -> 1.1349025 | W9: =S9/D9 -> 109.29198
U10: =SUM(D5:D9)/SUM(B5) -> 0.50773336 | V10: =SUM(E5:E9)/SUM(D5:D9) -> 5.779229 | W10: =SUM(H5:Q9)/SUM(D5:D9) -> 161.21033
A12: Lantai 1 | B12: ='REKAP Plat'!F51 -> 20.295768 | C12: Balok Lantai 1 | D12: ='REKAP Balok'!G332 -> 14.519641 | E12: ='REKAP Balok'!H332 -> 179.86435 | H12: ='REKAP Balok'!L332 -> 0 | I12: ='REKAP Balok'!M332 -> 140.51071 | J12: ='REKAP Balok'!N332 -> 768.95429 | K12: ='REKAP Balok'!O332 -> 1143.1415 | L12: ='REKAP Balok'!P332 -> 139.3144 | M12: ='REKAP Balok'!Q332 -> 0 | N12: ='REKAP Balok'!R332 -> 0 | O12: ='REKAP Balok'!S332 -> 0 | P12: ='REKAP Balok'!T332 -> 0 | Q12: 0 | S12: =SUM(H12:Q12) -> 2191.9209 | V12: =SUM(E12:G12)/D12 -> 12.387658 | W12: =S12/D12 -> 150.96247
C13: Plat Lantai | D13: ='REKAP Plat'!G51 -> 6.0887304 | E13: ='REKAP Plat'!I51 -> 45.939786 | F13: ='REKAP Plat'!H51 -> 0 | H13: 0 | I13: ='REKAP Plat'!N51 -> 0 | J13: ='REKAP Plat'!O51 -> 668.21462 | K13: ='REKAP Plat'!P51 -> 0 | L13: ='REKAP Plat'!Q51 -> 0 | M13: ='REKAP Plat'!R51 -> 0 | N13: 0 | O13: 0 | P13: 0 | Q13: 0 | S13: =SUM(H13:Q13) -> 668.21462 | V13: =SUM(E13:G13)/D13 -> 7.5450518 | W13: =S13/D13 -> 109.74613
C14: Retaining wall | D14: =SUM('Retaining Wall'!C170) -> 4.8345 | E14: =SUM('Retaining Wall'!D170) -> 64.46 | I14: =SUM('Retaining Wall'!E170) -> 0 | J14: =SUM('Retaining Wall'!F170) -> 638.8173 | K14: =SUM('Retaining Wall'!G170) -> 0 | L14: =SUM('Retaining Wall'!H170) -> 0 | M14: =SUM('Retaining Wall'!I170) -> 0 | S14: =SUM(H14:Q14) -> 638.8173 | V14: =SUM(E14:G14)/D14 -> 13.333333 | W14: =S14/D14 -> 132.1372
C15: Kolom | D15: ='Hasil-Kolom'!#REF! -> #REF! | E15: ='Hasil-Kolom'!#REF! -> #REF! | I15: ='Hasil-Kolom'!#REF! -> #REF! | J15: ='Hasil-Kolom'!#REF!+'Hasil-Kolom'!#REF! -> #REF! | K15: ='Hasil-Kolom'!#REF!+'Hasil-Kolom'!#REF! -> #REF! | L15: ='Hasil-Kolom'!#REF!+'Hasil-Kolom'!#REF! -> #REF! | M15: ='Hasil-Kolom'!#REF! -> #REF! | N15: ='Hasil-Kolom'!#REF! -> #REF! | O15: ='Hasil-Kolom'!#REF! -> #REF! | P15: ='Hasil-Kolom'!#REF! -> #REF! | S15: =SUM(H15:Q15) -> #REF! | V15: =SUM(E15:G15)/D15 -> #REF! | W15: =S15/D15 -> #REF!
U16: =SUM(D12:D15)/B12 -> #REF! | V16: =SUM(E8:E15)/SUM(D8:D15) -> #REF! | W16: =SUM(H8:Q15)/SUM(D8:D15) -> #REF!
A18: Lantai 2 | B18: ='REKAP Plat'!#REF! -> #REF! | C18: Balok Lantai 2 | D18: ='REKAP Balok'!#REF! -> #REF! | E18: ='REKAP Balok'!#REF! -> #REF! | H18: ='REKAP Balok'!#REF! -> #REF! | I18: ='REKAP Balok'!#REF! -> #REF! | J18: ='REKAP Balok'!#REF! -> #REF! | K18: ='REKAP Balok'!#REF! -> #REF! | L18: ='REKAP Balok'!#REF! -> #REF! | M18: ='REKAP Balok'!#REF! -> #REF! | N18: ='REKAP Balok'!#REF! -> #REF! | O18: ='REKAP Balok'!#REF! -> #REF! | P18: ='REKAP Balok'!#REF! -> #REF! | Q18: 0 | S18: =SUM(H18:Q18) -> #REF! | V18: =SUM(E18:G18)/D18 -> #REF! | W18: =S18/D18 -> #REF!
C19: Plat Lantai | D19: ='REKAP Plat'!#REF! -> #REF! | E19: ='REKAP Plat'!#REF! -> #REF! | H19: 0 | I19: ='REKAP Plat'!#REF! -> #REF! | J19: ='REKAP Plat'!#REF! -> #REF! | K19: ='REKAP Plat'!#REF! -> #REF! | L19: ='REKAP Plat'!#REF! -> #REF! | M19: ='REKAP Plat'!#REF! -> #REF! | N19: 0 | O19: 0 | P19: 0 | Q19: 0 | S19: =SUM(H19:Q19) -> #REF! | V19: =SUM(E19:G19)/D19 -> #REF! | W19: =S19/D19 -> #REF!
C20: Kolom | D20: ='Hasil-Kolom'!#REF! -> #REF! | E20: ='Hasil-Kolom'!#REF! -> #REF! | I20: ='Hasil-Kolom'!#REF! -> #REF! | J20: ='Hasil-Kolom'!#REF!+'Hasil-Kolom'!#REF! -> #REF! | K20: ='Hasil-Kolom'!#REF!+'Hasil-Kolom'!#REF! -> #REF! | L20: ='Hasil-Kolom'!#REF!+'Hasil-Kolom'!#REF! -> #REF! | M20: ='Hasil-Kolom'!#REF! -> #REF! | N20: ='Hasil-Kolom'!#REF! -> #REF! | O20: ='Hasil-Kolom'!#REF! -> #REF! | P20: ='Hasil-Kolom'!#REF! -> #REF! | S20: =SUM(H20:Q20) -> #REF! | V20: =SUM(E20:G20)/D20 -> #REF! | W20: =S20/D20 -> #REF!
U21: =SUM(D18:D20)/B18 -> #REF! | V21: =SUM(E18:E20)/SUM(D18:D20) -> #REF! | W21: =SUM(H18:Q20)/SUM(D18:D20) -> #REF!
A23: Lantai 3 | B23: ='REKAP Plat'!#REF! -> #REF! | C23: Balok Lantai 3 | D23: ='REKAP Balok'!#REF! -> #REF! | E23: ='REKAP Balok'!#REF! -> #REF! | H23: ='REKAP Balok'!#REF! -> #REF! | I23: ='REKAP Balok'!#REF! -> #REF! | J23: ='REKAP Balok'!#REF! -> #REF! | K23: ='REKAP Balok'!#REF! -> #REF! | L23: ='REKAP Balok'!#REF! -> #REF! | M23: ='REKAP Balok'!#REF! -> #REF! | N23: ='REKAP Balok'!#REF! -> #REF! | O23: ='REKAP Balok'!#REF! -> #REF! | P23: ='REKAP Balok'!#REF! -> #REF! | Q23: 0 | S23: =SUM(H23:Q23) -> #REF! | V23: =SUM(E23:G23)/D23 -> #REF! | W23: =S23/D23 -> #REF!
C24: Plat Lantai | D24: ='REKAP Plat'!#REF! -> #REF! | E24: ='REKAP Plat'!#REF! -> #REF! | H24: 0 | I24: ='REKAP Plat'!#REF! -> #REF! | J24: ='REKAP Plat'!#REF! -> #REF! | K24: ='REKAP Plat'!#REF! -> #REF! | L24: ='REKAP Plat'!#REF! -> #REF! | M24: ='REKAP Plat'!#REF! -> #REF! | N24: 0 | O24: 0 | P24: 0 | Q24: 0 | S24: =SUM(H24:Q24) -> #REF! | V24: =SUM(E24:G24)/D24 -> #REF! | W24: =S24/D24 -> #REF!
C25: Retaining wall | D25: =SUM('Retaining Wall'!#REF!) -> #REF! | E25: =SUM('Retaining Wall'!#REF!) -> #REF! | I25: =SUM('Retaining Wall'!#REF!) -> #REF! | J25: =SUM('Retaining Wall'!#REF!) -> #REF! | K25: =SUM('Retaining Wall'!#REF!) -> #REF! | L25: =SUM('Retaining Wall'!#REF!) -> #REF! | M25: =SUM('Retaining Wall'!I188) -> 0 | S25: =SUM(H25:Q25) -> #REF! | V25: =SUM(E25:G25)/D25 -> #REF! | W25: =S25/D25 -> #REF!
C26: Kolom | D26: ='Hasil-Kolom'!#REF! -> #REF! | E26: ='Hasil-Kolom'!#REF! -> #REF! | H26: 0 | I26: ='Hasil-Kolom'!#REF! -> #REF! | J26: ='Hasil-Kolom'!#REF!+'Hasil-Kolom'!#REF! -> #REF! | K26: ='Hasil-Kolom'!#REF!+'Hasil-Kolom'!#REF! -> #REF! | L26: ='Hasil-Kolom'!#REF!+'Hasil-Kolom'!#REF! -> #REF! | M26: ='Hasil-Kolom'!#REF! -> #REF! | N26: ='Hasil-Kolom'!#REF! -> #REF! | O26: ='Hasil-Kolom'!#REF! -> #REF! | P26: ='Hasil-Kolom'!#REF! -> #REF! | Q26: 0 | S26: =SUM(H26:Q26) -> #REF! | V26: =SUM(E26:G26)/D26 -> #REF! | W26: =S26/D26 -> #REF!
U27: =SUM(D23:D26)/B23 -> #REF! | V27: =SUM(E23:E26)/SUM(D23:D26) -> #REF! | W27: =SUM(H23:Q26)/SUM(D23:D26) -> #REF!
A29: Lantai Atap | B29: ='REKAP Plat'!#REF! -> #REF! | C29: Balok Lantai Atap | D29: ='REKAP Balok'!#REF! -> #REF! | E29: ='REKAP Balok'!#REF! -> #REF! | H29: ='REKAP Balok'!#REF! -> #REF! | I29: ='REKAP Balok'!#REF! -> #REF! | J29: ='REKAP Balok'!#REF! -> #REF! | K29: ='REKAP Balok'!#REF! -> #REF! | L29: ='REKAP Balok'!#REF! -> #REF! | M29: ='REKAP Balok'!#REF! -> #REF! | N29: ='REKAP Balok'!#REF! -> #REF! | O29: ='REKAP Balok'!#REF! -> #REF! | P29: ='REKAP Balok'!#REF! -> #REF! | Q29: 0 | S29: =SUM(H29:Q29) -> #REF! | V29: =SUM(E29:G29)/D29 -> #REF! | W29: =S29/D29 -> #REF!
C30: Plat Lantai | D30: ='REKAP Plat'!#REF! -> #REF! | E30: ='REKAP Plat'!#REF! -> #REF! | H30: 0 | I30: ='REKAP Plat'!#REF! -> #REF! | J30: ='REKAP Plat'!#REF! -> #REF! | K30: ='REKAP Plat'!#REF! -> #REF! | L30: ='REKAP Plat'!#REF! -> #REF! | M30: ='REKAP Plat'!#REF! -> #REF! | N30: 0 | O30: 0 | P30: 0 | Q30: 0 | S30: =SUM(H30:Q30) -> #REF! | V30: =SUM(E30:G30)/D30 -> #REF! | W30: =S30/D30 -> #REF!
U31: =SUM(D29:D30)/B29 -> #REF! | V31: =SUM(E29:E30)/SUM(D29:D30) -> #REF! | W31: =SUM(H29:Q30)/SUM(D29:D30) -> #REF!
A33: TOTAL | B33: =SUM(B4:B32) -> #REF! | D33: =SUM(D4:D32) -> #REF! | E33: =SUM(E4:E32) -> #REF! | F33: =SUM(F4:F32) -> 32.554986 | G33: =SUM(G4:G32) -> 91.046591 | H33: =SUM(H4:H32) -> #REF! | I33: =SUM(I4:I32) -> #REF! | J33: =SUM(J4:J32) -> #REF! | K33: =SUM(K4:K32) -> #REF! | ... Q33: =SUM(Q4:Q32) -> 0 | S33: =SUM(S4:S32) -> #REF!
R34: CEK | S34: =S33-SUM(H33:Q33) -> #REF!
A37: RASIO TOTAL
B38: Beton | C38: =D33/B33 -> #REF! | D38: m3/m2 luas bangunan
B39: Bekisting | C39: =SUM(E33:G33)/D33 -> #REF! | D39: m2/m3 beton
B40: Besi | C40: =S33/D33 -> #REF! | D40: kg/m3 beton
B42: waste besi | C42: 0.05
A44: Lantai | B44: Luas Bangunan | C44: Elemen Struktur | D44: Beton | E44: Bekisting | H44: Besi (LONJOR)
E45: Kayu | F45: Lantai Kerja | G45: Bata / Batako | H45: 6 | I45: 8 | J45: 10 | K45: 13 | L45: 16 | M45: 19 | N45: 22 | O45: 25 | P45: 29 | Q45: 32 | S45: TOTAL BESI (KG)
H46: 2.66 | I46: 4.74 | J46: 7.4 | K46: 12.5 | L46: 19 | M46: 26.8 | N46: 35.76 | O46: 46.25 | P46: 62.22 | Q46: 75.756
A49: =A5 -> Lantai Basement | B49: =B5 -> 288.09378 | C49: Pile cap | D49: =D5 -> 24.540556 | E49: =E5 -> 0 | F49: =F5 -> 6.5491084 | G49: =G5 -> 91.046591 | H49: =ROUNDUP(H5*(1+$C$42)/H$46,0) -> 0 | I49: =ROUNDUP(I5*(1+$C$42)/I$46,0) -> 0 | J49: =ROUNDUP(J5*(1+$C$42)/J$46,0) -> 0 | K49: =ROUNDUP(K5*(1+$C$42)/K$46,0) -> 121 | L49: =ROUNDUP(L5*(1+$C$42)/L$46,0) -> 101 | M49: =ROUNDUP(M5*(1+$C$42)/M$46,0) -> 11 | N49: =ROUNDUP(N5*(1+$C$42)/N$46,0) -> 0 | O49: =ROUNDUP(O5*(1+$C$42)/O$46,0) -> 0 | ... Q49: =ROUNDUP(Q5*(1+$C$42)/Q$46,0) -> 0 | S49: =SUMPRODUCT(H49:Q49,$H$46:$Q$46) -> 3726.3
C50: Kolom Lantai Basement | D50: =D6 -> 28.902461 | E50: =E6 -> 388.61904 | F50: =F6 -> 0 | G50: =G6 -> 0 | H50: =ROUNDUP(H6*(1+$C$42)/H$46,0) -> 0 | I50: =ROUNDUP(I6*(1+$C$42)/I$46,0) -> 0 | J50: =ROUNDUP(J6*(1+$C$42)/J$46,0) -> 389 | K50: =ROUNDUP(K6*(1+$C$42)/K$46,0) -> 0 | L50: =ROUNDUP(L6*(1+$C$42)/L$46,0) -> 243 | M50: =ROUNDUP(M6*(1+$C$42)/M$46,0) -> 0 | N50: =ROUNDUP(N6*(1+$C$42)/N$46,0) -> 0 | O50: =ROUNDUP(O6*(1+$C$42)/O$46,0) -> 0 | ... Q50: =ROUNDUP(Q6*(1+$C$42)/Q$46,0) -> 0 | S50: =SUMPRODUCT(H50:Q50,$H$46:$Q$46) -> 7495.6
C51: Balok Lantai Basement | D51: =D7 -> 32.3541 | E51: =E7 -> 300.411 | F51: =F7 -> 9.1139 | G51: =G7 -> 0 | H51: =ROUNDUP(H7*(1+$C$42)/H$46,0) -> 0 | I51: =ROUNDUP(I7*(1+$C$42)/I$46,0) -> 246 | J51: =ROUNDUP(J7*(1+$C$42)/J$46,0) -> 71 | K51: =ROUNDUP(K7*(1+$C$42)/K$46,0) -> 95 | L51: =ROUNDUP(L7*(1+$C$42)/L$46,0) -> 172 | M51: =ROUNDUP(M7*(1+$C$42)/M$46,0) -> 0 | N51: =ROUNDUP(N7*(1+$C$42)/N$46,0) -> 0 | O51: =ROUNDUP(O7*(1+$C$42)/O$46,0) -> 0 | ... Q51: =ROUNDUP(Q7*(1+$C$42)/Q$46,0) -> 0 | S51: =SUMPRODUCT(H51:Q51,$H$46:$Q$46) -> 6146.94
C52: Retaining wall | D52: =D8 -> 8.5733438 | E52: =E8 -> 114.31125 | F52: =F8 -> 0 | G52: =G8 -> 0 | H52: =ROUNDUP(H8*(1+$C$42)/H$46,0) -> 0 | I52: =ROUNDUP(I8*(1+$C$42)/I$46,0) -> 0 | J52: =ROUNDUP(J8*(1+$C$42)/J$46,0) -> 203 | K52: =ROUNDUP(K8*(1+$C$42)/K$46,0) -> 0 | L52: =ROUNDUP(L8*(1+$C$42)/L$46,0) -> 0 | M52: =ROUNDUP(M8*(1+$C$42)/M$46,0) -> 0 | N52: =ROUNDUP(N8*(1+$C$42)/N$46,0) -> 0 | O52: =ROUNDUP(O8*(1+$C$42)/O$46,0) -> 0 | ... Q52: =ROUNDUP(Q8*(1+$C$42)/Q$46,0) -> 0 | S52: =SUMPRODUCT(H52:Q52,$H$46:$Q$46) -> 1502.2
C53: Plat Lantai Bangunan | D53: =D9 -> 51.904365 | E53: =E9 -> 42.014415 | F53: =F9 -> 16.891977 | G53: =G9 -> 0 | H53: =ROUNDUP(H9*(1+$C$42)/H$46,0) -> 0 | I53: =ROUNDUP(I9*(1+$C$42)/I$46,0) -> 0 | J53: =ROUNDUP(J9*(1+$C$42)/J$46,0) -> 805 | K53: =ROUNDUP(K9*(1+$C$42)/K$46,0) -> 0 | L53: =ROUNDUP(L9*(1+$C$42)/L$46,0) -> 0 | M53: =ROUNDUP(M9*(1+$C$42)/M$46,0) -> 0 | N53: =ROUNDUP(N9*(1+$C$42)/N$46,0) -> 0 | O53: =ROUNDUP(O9*(1+$C$42)/O$46,0) -> 0 | ... Q53: =ROUNDUP(Q9*(1+$C$42)/Q$46,0) -> 0 | S53: =SUMPRODUCT(H53:Q53,$H$46:$Q$46) -> 5957
...

Sheet Retaining Wall
A3: No. | B3: Tipe RW | C3: Panjang | D3: Tinggi | E3: Tebal | F3: Tul. Vertikal (2 sisi) | I3: Extra Tul. Vertikal (1,5 m) (1 sisi) | L3: Tul. Kait | P3: Tul. Horizontal (2 sisi) | S3: Vol. Beton | T3: Vol. Bekisting | U3: Vol. Tul. Vertikal | V3: Vol. Tul. Kait | W3: Vol. Tul. Horizontal | Y3: rasio bekisting | Z3: rasio besi | AB3: Plesteran
F4: D | G4: Jarak | H4: Panjang Tul. | I4: D | J4: Jarak | K4: Panjang Tul. | L4: Jumlah | M4: D | N4: Jarak | O4: Panjang Tul. | P4: D | Q4: Jarak | R4: Panjang Tul.
C5: mm | D5: mm | E5: mm | F5: mm | G5: mm | H5: mm | I5: mm | J5: mm | K5: mm | M5: mm | N5: mm | O5: mm | P5: mm | Q5: mm | R5: mm | S5: m3 | T5: m2 | U5: kg | V5: kg | W5: kg
A7: Lantai 1
A8: 17 | B8: RW150 | C8: 4250 | D8: 5500 | E8: 150 | F8: 10 | G8: 200 | H8: =(D8+(2*40)*F8)*2 -> 12600 | J8: 100 | N8: 100 | P8: 10 | Q8: 200 | R8: =(C8+(6*40+11*50)*P8)*2 -> 24300 | S8: =C8*D8*E8/1000000000 -> 3.50625 | T8: =2*C8*D8/1000000 -> 46.75 | U8: =0.006165*(F8^2*H8*(ROUND(C8/G8,0)+1)+I8^2*K8*(ROUND(C8/J8,0)+1))/1000 -> 170.8938 | V8: =0.006165*M8^2*O8*(ROUND(C8/N8,0)+1)/1000*L8 -> 0 | W8: =0.006165*P8^2*R8*(ROUND(D8/Q8,0)+1)/1000 -> 434.44755 | Y8: =T8/S8 -> 13.333333 | Z8: =SUM(U8:W8)/S8 -> 172.64637 | AB8: =T8 -> 46.75
A9: 19 | B9: Pagar Alas | C9: 20000 | D9: 1000 | E9: 170 | F9: 10 | G9: 200 | H9: =(D9+(2*40)*F9)*2 -> 3600 | J9: 100 | N9: 100 | P9: 10 | Q9: 200 | R9: =(C9+(2*40+2*50)*P9)*2 -> 43600 | S9: =C9*D9*E9/1000000000 -> 3.4 | T9: =C9*D9/1000000 -> 20 | U9: =0.006165*(F9^2*H9*(ROUND(C9/G9,0)+1)+I9^2*K9*(ROUND(C9/J9,0)+1))/1000 -> 224.1594 | V9: =0.006165*M9^2*O9*(ROUND(C9/N9,0)+1)/1000*L9 -> 0 | W9: =0.006165*P9^2*R9*(ROUND(D9/Q9,0)+1)/1000 -> 161.2764 | Y9: =T9/S9 -> 5.8823529 | Z9: =SUM(U9:W9)/S9 -> 113.36347 | AB9: =T9 -> 20
A10: =A9+1 -> 20 | B10: Pagar Alas | C10: 21795 | D10: 1000 | E10: 170 | F10: 10 | G10: 200 | H10: =(D10+(2*40)*F10)*2 -> 3600 | J10: 100 | N10: 100 | P10: 10 | Q10: 200 | R10: =(C10+(2*40+2*50)*P10)*2 -> 47190 | S10: =C10*D10*E10/1000000000 -> 3.70515 | T10: =2*C10*D10/1000000 -> 43.59 | U10: =0.006165*(F10^2*H10*(ROUND(C10/G10,0)+1)+I10^2*K10*(ROUND(C10/J10,0)+1))/1000 -> 244.134 | V10: =0.006165*M10^2*O10*(ROUND(C10/N10,0)+1)/1000*L10 -> 0 | W10: =0.006165*P10^2*R10*(ROUND(D10/Q10,0)+1)/1000 -> 174.55581 | Y10: =T10/S10 -> 11.764706 | Z10: =SUM(U10:W10)/S10 -> 113.00212 | AB10: =T10 -> 43.59
A11: =A10+1 -> 21 | B11: Pagar Alas | C11: 34285 | D11: 1000 | E11: 170 | F11: 10 | G11: 200 | H11: =(D11+(2*40)*F11)*2 -> 3600 | J11: 100 | N11: 100 | P11: 10 | Q11: 200 | R11: =(C11+(8*40+2*50)*P11)*2 -> 76970 | S11: =C11*D11*E11/1000000000 -> 5.82845 | T11: =2*C11*D11/1000000 -> 68.57 | U11: =0.006165*(F11^2*H11*(ROUND(C11/G11,0)+1)+I11^2*K11*(ROUND(C11/J11,0)+1))/1000 -> 381.7368 | V11: =0.006165*M11^2*O11*(ROUND(C11/N11,0)+1)/1000*L11 -> 0 | W11: =0.006165*P11^2*R11*(ROUND(D11/Q11,0)+1)/1000 -> 284.71203 | Y11: =T11/S11 -> 11.764706 | Z11: =SUM(U11:W11)/S11 -> 114.34409 | AB11: =T11/2 -> 34.285
A12: 19 | B12: Pagar Alas | C12: 20000 | D12: 4500 | E12: 100 | F12: 10 | G12: 300 | H12: =(D12+(2*40)*F12) -> 5300 | J12: 100 | N12: 100 | P12: 10 | Q12: 300 | R12: =(C12+(2*40+1*50)*P12) -> 21300 | S12: =C12*D12*E12/1000000000 -> 9 | T12: =C12*D12/1000000 -> 90 | U12: =0.006165*(F12^2*H12*(ROUND(C12/G12,0)+1)+I12^2*K12*(ROUND(C12/J12,0)+1))/1000 -> 222.1866 | V12: =0.006165*M12^2*O12*(ROUND(C12/N12,0)+1)/1000*L12 -> 0 | W12: =0.006165*P12^2*R12*(ROUND(D12/Q12,0)+1)/1000 -> 210.1032 | Y12: =T12/S12 -> 10 | Z12: =SUM(U12:W12)/S12 -> 48.0322 | AB12: =T12 -> 90
A13: =A12+1 -> 20 | B13: Pagar Alas | C13: 21795 | D13: 4500 | E13: 100 | F13: 10 | G13: 300 | H13: =(D13+(2*40)*F13) -> 5300 | J13: 100 | N13: 100 | P13: 10 | Q13: 300 | R13: =(C13+(2*40+1*50)*P13) -> 23095 | S13: =C13*D13*E13/1000000000 -> 9.80775 | T13: =2*C13*D13/1000000 -> 196.155 | U13: =0.006165*(F13^2*H13*(ROUND(C13/G13,0)+1)+I13^2*K13*(ROUND(C13/J13,0)+1))/1000 -> 241.7913 | V13: =0.006165*M13^2*O13*(ROUND(C13/N13,0)+1)/1000*L13 -> 0 | W13: =0.006165*P13^2*R13*(ROUND(D13/Q13,0)+1)/1000 -> 227.80908 | Y13: =T13/S13 -> 20 | Z13: =SUM(U13:W13)/S13 -> 47.880541 | AB13: =T13 -> 196.155
B14: Pagar Alas
A15: =A11+1 -> 22 | B15: RW150 | C15: 20090 | D15: 1000 | E15: 150 | F15: 10 | G15: 200 | H15: =(D15+(2*40)*F15)*2 -> 3600 | J15: 100 | N15: 100 | P15: 10 | Q15: 200 | R15: =(C15+(8*40+3*50)*P15)*2 -> 49580 | S15: =C15*D15*E15/1000000000 -> 3.0135 | T15: =2*C15*D15/1000000 -> 40.18 | U15: =0.006165*(F15^2*H15*(ROUND(C15/G15,0)+1)+I15^2*K15*(ROUND(C15/J15,0)+1))/1000 -> 224.1594 | V15: =0.006165*M15^2*O15*(ROUND(C15/N15,0)+1)/1000*L15 -> 0 | W15: =0.006165*P15^2*R15*(ROUND(D15/Q15,0)+1)/1000 -> 183.39642 | Y15: =T15/S15 -> 13.333333 | Z15: =SUM(U15:W15)/S15 -> 135.24334 | AB15: =T15/2 -> 20.09
A16: =A15+1 -> 23 | B16: RW150 | C16: 17775 | D16: 400 | E16: 150 | F16: 10 | G16: 200 | H16: =(D16+(2*40)*F16)*2 -> 2400 | J16: 100 | N16: 100 | P16: 10 | Q16: 200 | R16: =(C16+(4*40+0*50)*P16)*2 -> 38750 | S16: =C16*D16*E16/1000000000 -> 1.0665 | T16: =2*C16*D16/1000000 -> 14.22 | U16: =0.006165*(F16^2*H16*(ROUND(C16/G16,0)+1)+I16^2*K16*(ROUND(C16/J16,0)+1))/1000 -> 133.164 | V16: =0.006165*M16^2*O16*(ROUND(C16/N16,0)+1)/1000*L16 -> 0 | W16: =0.006165*P16^2*R16*(ROUND(D16/Q16,0)+1)/1000 -> 71.668125 | Y16: =T16/S16 -> 13.333333 | Z16: =SUM(U16:W16)/S16 -> 192.06013 | AB16: =T16/2 -> 7.11
A17: =A16+1 -> 24 | B17: Kolam Renang | C17: 22050 | D17: 1700 | E17: 200 | F17: 13 | G17: 150 | H17: =(D17+(2*40)*F17)*2 -> 5480 | J17: 100 | N17: 100 | P17: 10 | Q17: 150 | R17: =(C17+(4*40+0*50)*P17)*2 -> 47300 | S17: =C17*D17*E17/1000000000 -> 7.497 | T17: =2*C17*D17/1000000 -> 74.97 | U17: =0.006165*(F17^2*H17*(ROUND(C17/G17,0)+1)+I17^2*K17*(ROUND(C17/J17,0)+1))/1000 -> 845.01041 | V17: =0.006165*M17^2*O17*(ROUND(C17/N17,0)+1)/1000*L17 -> 0 | W17: =0.006165*P17^2*R17*(ROUND(D17/Q17,0)+1)/1000 -> 349.9254 | Y17: =T17/S17 -> 10 | Z17: =SUM(U17:W17)/S17 -> 159.38853 | AB17: =T17/2 -> 37.485
A18: =A17+1 -> 25 | B18: RW150 | C18: 600 | D18: 400 | E18: 150 | F18: 10 | G18: 200 | H18: =(D18+(2*40)*F18)*2 -> 2400 | J18: 100 | N18: 100 | P18: 10 | Q18: 200 | R18: =(C18+(4*40+1*50)*P18)*2 -> 5400 | S18: =C18*D18*E18/1000000000 -> 0.036 | T18: =2*C18*D18/1000000 -> 0.48 | U18: =0.006165*(F18^2*H18*(ROUND(C18/G18,0)+1)+I18^2*K18*(ROUND(C18/J18,0)+1))/1000 -> 5.9184 | V18: =0.006165*M18^2*O18*(ROUND(C18/N18,0)+1)/1000*L18 -> 0 | W18: =0.006165*P18^2*R18*(ROUND(D18/Q18,0)+1)/1000 -> 9.9873 | Y18: =T18/S18 -> 13.333333 | Z18: =SUM(U18:W18)/S18 -> 441.825 | AB18: =T18/2 -> 0.24
A19: =A18+1 -> 26 | B19: Tanggulan KM | C19: 8950 | D19: 200 | E19: 150 | F19: 10 | G19: 200 | H19: =(D19+(2*40)*F19)*2 -> 2000 | J19: 100 | N19: 100 | P19: 10 | Q19: 200 | R19: =(C19+(4*40+1*50)*P19)*2 -> 22100 | S19: =C19*D19*E19/1000000000 -> 0.2685 | T19: =2*C19*D19/1000000 -> 3.58 | U19: =0.006165*(F19^2*H19*(ROUND(C19/G19,0)+1)+I19^2*K19*(ROUND(C19/J19,0)+1))/1000 -> 56.718 | V19: =0.006165*M19^2*O19*(ROUND(C19/N19,0)+1)/1000*L19 -> 0 | W19: =0.006165*P19^2*R19*(ROUND(D19/Q19,0)+1)/1000 -> 27.2493 | Y19: =T19/S19 -> 13.333333 | Z19: =SUM(U19:W19)/S19 -> 312.72737 | AB19: =T19/2 -> 1.79
A20: =A19+1 -> 27 | B20: RW150 | C20: 5775 | D20: 750 | E20: 150 | F20: 10 | G20: 200 | H20: =(D20+(2*40)*F20)*2 -> 3100 | J20: 100 | N20: 100 | P20: 10 | Q20: 200 | R20: =(C20+(4*40+1*50)*P20)*2 -> 15750 | S20: =C20*D20*E20/1000000000 -> 0.6496875 | T20: =2*C20*D20/1000000 -> 8.6625 | U20: =0.006165*(F20^2*H20*(ROUND(C20/G20,0)+1)+I20^2*K20*(ROUND(C20/J20,0)+1))/1000 -> 57.3345 | V20: =0.006165*M20^2*O20*(ROUND(C20/N20,0)+1)/1000*L20 -> 0 | W20: =0.006165*P20^2*R20*(ROUND(D20/Q20,0)+1)/1000 -> 48.549375 | Y20: =T20/S20 -> 13.333333 | Z20: =SUM(U20:W20)/S20 -> 162.97662 | AB20: =T20/2 -> 4.33125
A21: =A20+1 -> 28 | B21: RW150 | C21: 3325 | D21: 500 | E21: 150 | F21: 10 | G21: 200 | H21: =(D21+(2*40)*F21)*2 -> 2600 | J21: 100 | N21: 100 | P21: 10 | Q21: 200 | R21: =(C21+(4*40+1*50)*P21)*2 -> 10850 | S21: =C21*D21*E21/1000000000 -> 0.249375 | T21: =2*C21*D21/1000000 -> 3.325 | U21: =0.006165*(F21^2*H21*(ROUND(C21/G21,0)+1)+I21^2*K21*(ROUND(C21/J21,0)+1))/1000 -> 28.8522 | V21: =0.006165*M21^2*O21*(ROUND(C21/N21,0)+1)/1000*L21 -> 0 | W21: =0.006165*P21^2*R21*(ROUND(D21/Q21,0)+1)/1000 -> 26.7561 | Y21: =T21/S21 -> 13.333333 | Z21: =SUM(U21:W21)/S21 -> 222.99068 | AB21: =T21/2 -> 1.6625
A22: =A21+1 -> 29 | B22: RW150 | C22: 2775 | D22: 125 | E22: 150 | F22: 10 | G22: 200 | H22: =(D22+(2*40)*F22)*2 -> 1850 | J22: 100 | N22: 100 | P22: 10 | Q22: 200 | R22: =(C22+(4*40+1*50)*P22)*2 -> 9750 | S22: =C22*D22*E22/1000000000 -> 0.05203125 | T22: =2*C22*D22/1000000 -> 0.69375 | U22: =0.006165*(F22^2*H22*(ROUND(C22/G22,0)+1)+I22^2*K22*(ROUND(C22/J22,0)+1))/1000 -> 17.107875 | V22: =0.006165*M22^2*O22*(ROUND(C22/N22,0)+1)/1000*L22 -> 0 | W22: =0.006165*P22^2*R22*(ROUND(D22/Q22,0)+1)/1000 -> 12.02175 | Y22: =T22/S22 -> 13.333333 | Z22: =SUM(U22:W22)/S22 -> 559.84865 | AB22: =T22/2 -> 0.346875
A23: =A22+1 -> 30 | B23: Lift | C23: =8800-4000 -> 4800 | D23: 6000 | E23: 170 | F23: 10 | G23: 100 | H23: =(D23+(2*40)*F23)*2 -> 13600 | J23: 100 | L23: 6 | M23: 10 | N23: 100 | O23: 300 | P23: 13 | Q23: 100 | R23: =(C23+(4*40+0*50)*P23)*2 -> 13760 | S23: =C23*D23*E23/1000000000 -> 4.896 | T23: =2*C23*D23/1000000 -> 57.6 | U23: =0.006165*(F23^2*H23*(ROUND(C23/G23,0)+1)+I23^2*K23*(ROUND(C23/J23,0)+1))/1000 -> 410.8356 | V23: =0.006165*M23^2*O23*(ROUND(C23/N23,0)+1)/1000*L23 -> 54.3753 | W23: =0.006165*P23^2*R23*(ROUND(D23/Q23,0)+1)/1000 -> 874.51659 | Y23: =T23/S23 -> 11.764706 | Z23: =SUM(U23:W23)/S23 -> 273.63715 | AB23: =T23/2 -> 28.8
A24: Lantai 2
A25: 23 | B25: Pagar Alas Lt2 | C25: 9000 | D25: 4500 | E25: 100 | F25: 10 | G25: 300 | H25: =(D25+(2*40)*F25) -> 5300 | J25: 100 | N25: 100 | P25: 10 | Q25: 300 | R25: =(C25+(2*40+50)*P25) -> 10300 | S25: =C25*D25*E25/1000000000 -> 4.05 | T25: =C25*D25/1000000 -> 40.5 | U25: =0.006165*(F25^2*H25*(ROUND(C25/G25,0)+1)+I25^2*K25*(ROUND(C25/J25,0)+1))/1000 -> 101.29095 | V25: =0.006165*M25^2*O25*(ROUND(C25/N25,0)+1)/1000*L25 -> 0 | W25: =0.006165*P25^2*R25*(ROUND(D25/Q25,0)+1)/1000 -> 101.5992 | Y25: =T25/S25 -> 10 | Z25: =SUM(U25:W25)/S25 -> 50.096333 | AB25: =T25/2 -> 20.25
A26: =A25+1 -> 24 | B26: Pagar Alas Lt2 | C26: 15000 | D26: 4500 | E26: 100 | F26: 10 | G26: 300 | H26: =(D26+(2*40)*F26) -> 5300 | J26: 100 | N26: 100 | P26: 10 | Q26: 300 | R26: =(C26+(2*40+1*50)*P26) -> 16300 | S26: =C26*D26*E26/1000000000 -> 6.75 | T26: =C26*D26/1000000 -> 67.5 | U26: =0.006165*(F26^2*H26*(ROUND(C26/G26,0)+1)+I26^2*K26*(ROUND(C26/J26,0)+1))/1000 -> 166.63995 | V26: =0.006165*M26^2*O26*(ROUND(C26/N26,0)+1)/1000*L26 -> 0 | W26: =0.006165*P26^2*R26*(ROUND(D26/Q26,0)+1)/1000 -> 160.7832 | Y26: =T26/S26 -> 10 | Z26: =SUM(U26:W26)/S26 -> 48.507133 | AB26: =T26/2 -> 33.75
A27: =A26+1 -> 25 | B27: Pagar Alas Lt2 | C27: 11300 | D27: 200 | E27: 150 | F27: 10 | G27: 200 | H27: =(D27+(2*40)*F27)*2 -> 2000 | J27: 100 | N27: 100 | P27: 10 | Q27: 200 | R27: =(C27+(2*40+0*50)*P27)*2 -> 24200 | S27: =C27*D27*E27/1000000000 -> 0.339 | T27: =2*C27*D27/1000000 -> 4.52 | U27: =0.006165*(F27^2*H27*(ROUND(C27/G27,0)+1)+I27^2*K27*(ROUND(C27/J27,0)+1))/1000 -> 71.514 | V27: =0.006165*M27^2*O27*(ROUND(C27/N27,0)+1)/1000*L27 -> 0 | W27: =0.006165*P27^2*R27*(ROUND(D27/Q27,0)+1)/1000 -> 29.8386 | Y27: =T27/S27 -> 13.333333 | Z27: =SUM(U27:W27)/S27 -> 298.97522 | AB27: =T27/2 -> 2.26
A28: =A27+1 -> 26 | B28: Tanggulan Lt2 | C28: 8600 | D28: 200 | E28: 150 | F28: 10 | G28: 200 | H28: =(D28+(2*40)*F28)*2 -> 2000 | J28: 100 | N28: 100 | P28: 10 | Q28: 200 | R28: =(C28+(2*40+0*50)*P28)*2 -> 18800 | S28: =C28*D28*E28/1000000000 -> 0.258 | T28: =2*C28*D28/1000000 -> 3.44 | U28: =0.006165*(F28^2*H28*(ROUND(C28/G28,0)+1)+I28^2*K28*(ROUND(C28/J28,0)+1))/1000 -> 54.252 | V28: =0.006165*M28^2*O28*(ROUND(C28/N28,0)+1)/1000*L28 -> 0 | W28: =0.006165*P28^2*R28*(ROUND(D28/Q28,0)+1)/1000 -> 23.1804 | Y28: =T28/S28 -> 13.333333 | Z28: =SUM(U28:W28)/S28 -> 300.12558 | AB28: =T28/2 -> 1.72
A29: =A28+1 -> 27 | B29: Tanggulan Lt2 | C29: 9450 | D29: 200 | E29: 150 | F29: 10 | G29: 200 | H29: =(D29+(2*40)*F29)*2 -> 2000 | J29: 100 | N29: 100 | P29: 10 | Q29: 200 | R29: =(C29+(2*40+0*50)*P29)*2 -> 20500 | S29: =C29*D29*E29/1000000000 -> 0.2835 | T29: =2*C29*D29/1000000 -> 3.78 | U29: =0.006165*(F29^2*H29*(ROUND(C29/G29,0)+1)+I29^2*K29*(ROUND(C29/J29,0)+1))/1000 -> 59.184 | V29: =0.006165*M29^2*O29*(ROUND(C29/N29,0)+1)/1000*L29 -> 0 | W29: =0.006165*P29^2*R29*(ROUND(D29/Q29,0)+1)/1000 -> 25.2765 | Y29: =T29/S29 -> 13.333333 | Z29: =SUM(U29:W29)/S29 -> 297.92063 | AB29: =T29/2 -> 1.89
A30: =A29+1 -> 28 | B30: Tanggulan Lt2 | C30: 12600 | D30: 200 | E30: 150 | F30: 10 | G30: 200 | H30: =(D30+(2*40)*F30)*2 -> 2000 | J30: 100 | N30: 100 | P30: 10 | Q30: 200 | R30: =(C30+(2*40+0*50)*P30)*2 -> 26800 | S30: =C30*D30*E30/1000000000 -> 0.378 | T30: =2*C30*D30/1000000 -> 5.04 | U30: =0.006165*(F30^2*H30*(ROUND(C30/G30,0)+1)+I30^2*K30*(ROUND(C30/J30,0)+1))/1000 -> 78.912 | V30: =0.006165*M30^2*O30*(ROUND(C30/N30,0)+1)/1000*L30 -> 0 | W30: =0.006165*P30^2*R30*(ROUND(D30/Q30,0)+1)/1000 -> 33.0444 | Y30: =T30/S30 -> 13.333333 | Z30: =SUM(U30:W30)/S30 -> 296.18095 | AB30: =T30/2 -> 2.52
A31: =A30+1 -> 29 | B31: Tanggulan Lt2 | C31: 800 | D31: 200 | E31: 150 | F31: 10 | G31: 200 | H31: =(D31+(2*40)*F31)*2 -> 2000 | J31: 100 | N31: 100 | P31: 10 | Q31: 200 | R31: =(C31+(2*40+1*50)*P31)*2 -> 4200 | S31: =C31*D31*E31/1000000000 -> 0.024 | T31: =2*C31*D31/1000000 -> 0.32 | U31: =0.006165*(F31^2*H31*(ROUND(C31/G31,0)+1)+I31^2*K31*(ROUND(C31/J31,0)+1))/1000 -> 6.165 | V31: =0.006165*M31^2*O31*(ROUND(C31/N31,0)+1)/1000*L31 -> 0 | W31: =0.006165*P31^2*R31*(ROUND(D31/Q31,0)+1)/1000 -> 5.1786 | Y31: =T31/S31 -> 13.333333 | Z31: =SUM(U31:W31)/S31 -> 472.65 | AB31: =T31/2 -> 0.16
A32: =A31+1 -> 30 | B32: Tanggulan Lt2 | C32: 1080 | D32: 200 | E32: 150 | F32: 10 | G32: 200 | H32: =(D32+(2*40)*F32)*2 -> 2000 | J32: 100 | N32: 100 | P32: 10 | Q32: 200 | R32: =(C32+(2*40+0*50)*P32)*2 -> 3760 | S32: =C32*D32*E32/1000000000 -> 0.0324 | T32: =2*C32*D32/1000000 -> 0.432 | U32: =0.006165*(F32^2*H32*(ROUND(C32/G32,0)+1)+I32^2*K32*(ROUND(C32/J32,0)+1))/1000 -> 7.398 | V32: =0.006165*M32^2*O32*(ROUND(C32/N32,0)+1)/1000*L32 -> 0 | W32: =0.006165*P32^2*R32*(ROUND(D32/Q32,0)+1)/1000 -> 4.63608 | Y32: =T32/S32 -> 13.333333 | Z32: =SUM(U32:W32)/S32 -> 371.42222 | AB32: =T32/2 -> 0.216
A33: =A32+1 -> 31 | B33: Tanggulan Lt2 | C33: 4950 | D33: 200 | E33: 150 | F33: 10 | G33: 200 | H33: =(D33+(2*40)*F33)*2 -> 2000 | J33: 100 | N33: 100 | P33: 10 | Q33: 200 | R33: =(C33+(2*40+0*50)*P33)*2 -> 11500 | S33: =C33*D33*E33/1000000000 -> 0.1485 | T33: =2*C33*D33/1000000 -> 1.98 | U33: =0.006165*(F33^2*H33*(ROUND(C33/G33,0)+1)+I33^2*K33*(ROUND(C33/J33,0)+1))/1000 -> 32.058 | V33: =0.006165*M33^2*O33*(ROUND(C33/N33,0)+1)/1000*L33 -> 0 | W33: =0.006165*P33^2*R33*(ROUND(D33/Q33,0)+1)/1000 -> 14.1795 | Y33: =T33/S33 -> 13.333333 | Z33: =SUM(U33:W33)/S33 -> 311.36364 | AB33: =T33/2 -> 0.99
